As a computer science student, you may encounter errors while running code. These errors can be caused by a variety of reasons, such as incorrect input, network issues, or bugs in the program. Handling these errors is an essential part of programming, and that's where try, except, and finally blocks come in.


Think of these blocks as the safety nets in a circus performance. Imagine you're a tightrope walker, and you're performing in front of a live audience. You've practiced your routine for weeks, and you're confident that you can make it to the other end without falling. However, there's always a chance that something unexpected could happen during the performance. Maybe there's a gust of wind, or you lose your balance for a split second.


To prepare for these unexpected situations, you have a safety net below you. If you were to fall, the safety net would catch you and prevent you from getting hurt. The safety net is like a try block in programming. It's a block of code that you wrap around the code that could potentially cause an error.


If an error occurs within the try block, the program doesn't crash. Instead, the program jumps to the except block, which is like the safety net catching you. The except block is where you handle the error and take appropriate action, such as displaying an error message to the user or logging the error for debugging purposes.


Finally, there's the finally block. This block is like the crew that helps you get off the safety net and back onto the tightrope. The finally block is optional, but it's useful for performing cleanup operations, such as closing files or releasing resources, regardless of whether an error occurred or not.


In summary, try, except, and finally blocks are like safety nets in a circus performance. They help you handle errors and prevent your program from crashing.


Understanding Try, Except, Finally Blocks in Python
===================================================


In Python, we sometimes come across situations where our code may throw an error or an exception. These errors may occur due to various reasons such as incorrect user input, unexpected system behavior, or programming mistakes. 


To handle such situations, we use try, except, and finally blocks in Python. These blocks help us to gracefully handle errors in our code and prevent our program from crashing.


Try Block
---------


A try block is used to enclose the code that may throw an error. We put the potentially problematic code inside the try block. If an error occurs inside the try block, the program will catch and handle the error instead of crashing. 


Except Block
------------


An except block is used to handle the errors that occur inside the try block. If an error occurs inside the try block, the program jumps to the except block and executes the code inside it. 


Finally Block
-------------


A finally block is used to execute code that we want to run regardless of whether an error occurs or not. It is executed after the try and except blocks are executed.


Now, let's look at a concrete example to understand the usage of try, except, and finally blocks.


```python


A function to divide two numbers
================================


def divide(num1, num2):
 try:
 result = num1 / num2
 print("The result is:", result)
 except ZeroDivisionError:
 print("Error: Cannot divide by zero!")
 finally:
 print("This code will execute no matter what.")


Test the function with different inputs
=======================================


divide(10, 2)
divide(5, 0)
```


In the above code, we have defined a function `divide` that takes two arguments `num1` and `num2`. We have put the code that potentially throws an error inside the try block. If an error occurs while dividing `num1` by `num2`, the program will jump to the except block and print an error message. 


The finally block is used to print a message after the try and except blocks are executed. This message will be printed regardless of whether an error occurs or not.


When we call the `divide` function with `num1=10` and `num2=2`, the function executes successfully and prints the result `The result is: 5.0`. When we call the function again with `num1=5` and `num2=0`, an error occurs due to division by zero. The program jumps to the except block and prints the error message `Error: Cannot divide by zero!`. The finally block is executed after the except block and prints the message `This code will execute no matter what.`. 


In conclusion, try, except, and finally blocks are essential in Python programming to handle errors gracefully and prevent our program from crashing due to unexpected errors.


Try, Except, Finally Blocks
---------------------------


In programming, we often want to anticipate and handle errors that may occur while running our code. One way of doing this is by using try-except-finally blocks. 


### Example 1: Division by Zero


Let's say we want to divide a number by another number, but the second number is zero. This would result in an error that could terminate the program. We can use a try-except block to handle this error and continue running the program.


`python
try:
 x = 10
 y = 0
 z = x/y
except ZeroDivisionError:
 print("Error: division by zero")`


In this example, we try to divide the number 10 by 0, which is not possible. Instead of the program crashing, the except block catches the ZeroDivisionError and prints an error message. 


### Example 2: File Handling


Another common use case for try-except blocks is with file handling. When we open a file, there is a chance that the file may not exist or we may not have the correct permissions to access it. We can use a try-except block to handle this error and inform the user.


`python
try:
 file = open("example.txt", "r")
 file_contents = file.read()
 print(file_contents)
except FileNotFoundError:
 print("Error: file not found")
finally:
 file.close()`


In this example, we try to open a file called "example.txt" in read mode. If the file does not exist, the except block catches the FileNotFoundError and prints an error message. Additionally, the finally block ensures that the file is always closed, even if an error occurs.


### Example 3: Database Connection


Finally, let's say we want to connect to a database, but there is a chance that the database may not be available or we may not have the correct login credentials. We can use a try-except block to handle this error and gracefully exit the program.


```python
import psycopg2


try:
 conn = psycopg2.connect(
 host="localhost",
 database="example",
 user="user",
 password="password"
 )
 cur = conn.cursor()
 cur.execute("SELECT \* FROM table")
 rows = cur.fetchall()
 print(rows)
except psycopg2.OperationalError:
 print("Error: could not connect to database")
finally:
 cur.close()
 conn.close()
```


In this example, we try to connect to a database using the psycopg2 library. If we are unable to connect, the except block catches the psycopg2.OperationalError and prints an error message. Additionally, the finally block ensures that the database connection is always closed, even if an error occurs.


By using try-except-finally blocks, we can gracefully handle errors that may occur while running our code and ensure that our programs continue running as expected.


1. What is the use of the 'try-except' block in Python?
a) To execute a block of code only if a certain condition is met
b) To handle errors that may occur during program execution
c) To stop the execution of the program immediately
d) To skip a certain block of code
2. In a 'try-except' block, which part of the code will be executed if an error occurs?
a) The 'try' block
b) The 'except' block
c) The 'finally' block
d) None of the above
3. Which keyword is used to define the 'finally' block in a 'try-except' block?
a) try
b) except
c) finally
d) catch
4. What happens if an error occurs in the 'finally' block of a 'try-except' block?
a) The error is ignored and program execution continues
b) The program crashes and stops executing immediately
c) The error is caught by the 'except' block and handled accordingly
d) None of the above
5. What is the purpose of the 'finally' block in a 'try-except' block?
a) To execute a block of code only if a certain condition is met
b) To handle errors that may occur during program execution
c) To always execute a certain block of code, regardless of whether an error occurred or not
d) To skip a certain block of code.


